2023-10-19 11:21:24,019 INFO    MainThread:16838 [wandb_setup.py:_flush():76] Current SDK version is 0.15.10
2023-10-19 11:21:24,019 INFO    MainThread:16838 [wandb_setup.py:_flush():76] Configure stats pid to 16838
2023-10-19 11:21:24,019 INFO    MainThread:16838 [wandb_setup.py:_flush():76] Loading settings from /home/yasin/.config/wandb/settings
2023-10-19 11:21:24,019 INFO    MainThread:16838 [wandb_setup.py:_flush():76] Loading settings from /home/yasin/notebooks/phi4/wandb/settings
2023-10-19 11:21:24,019 INFO    MainThread:16838 [wandb_setup.py:_flush():76] Loading settings from environment variables: {'api_key': '***REDACTED***'}
2023-10-19 11:21:24,019 INFO    MainThread:16838 [wandb_setup.py:_flush():76] Inferring run settings from compute environment: {'program_relpath': 'train.py', 'program': '/home/yasin/notebooks/phi4/train.py'}
2023-10-19 11:21:24,019 INFO    MainThread:16838 [wandb_setup.py:_flush():76] Applying login settings: {'api_key': '***REDACTED***'}
2023-10-19 11:21:24,019 INFO    MainThread:16838 [wandb_setup.py:_flush():76] Applying login settings: {'api_key': '***REDACTED***'}
2023-10-19 11:21:24,019 INFO    MainThread:16838 [wandb_init.py:_log_setup():524] Logging user logs to /home/yasin/notebooks/phi4/wandb/run-20231019_112124-60kok29u/logs/debug.log
2023-10-19 11:21:24,019 INFO    MainThread:16838 [wandb_init.py:_log_setup():525] Logging internal logs to /home/yasin/notebooks/phi4/wandb/run-20231019_112124-60kok29u/logs/debug-internal.log
2023-10-19 11:21:24,019 INFO    MainThread:16838 [wandb_init.py:init():564] calling init triggers
2023-10-19 11:21:24,020 INFO    MainThread:16838 [wandb_init.py:init():571] wandb.init called with sweep_config: {}
config: {'learning_rate': 4e-06, 'batch_size': 8000, 'architecture': 'NICE', 'dataset': 'phi4'}
2023-10-19 11:21:24,020 INFO    MainThread:16838 [wandb_init.py:init():614] starting backend
2023-10-19 11:21:24,020 INFO    MainThread:16838 [wandb_init.py:init():618] setting up manager
2023-10-19 11:21:24,021 INFO    MainThread:16838 [backend.py:_multiprocessing_setup():105] multiprocessing start_methods=fork,spawn,forkserver, using: spawn
2023-10-19 11:21:24,022 INFO    MainThread:16838 [wandb_init.py:init():624] backend started and connected
2023-10-19 11:21:24,024 INFO    MainThread:16838 [wandb_init.py:init():715] updated telemetry
2023-10-19 11:21:24,037 INFO    MainThread:16838 [wandb_init.py:init():748] communicating run to backend with 90.0 second timeout
2023-10-19 11:21:24,375 ERROR   MainThread:16838 [wandb_init.py:init():774] encountered error: The API key you provided is either invalid or missing.  If the `WANDB_API_KEY` environment variable is set, make sure it is correct. Otherwise, to resolve this issue, you may try running the 'wandb login --relogin' command. If you are using a local server, make sure that you're using the correct hostname. If you're not sure, you can try logging in again using the 'wandb login --relogin --host [hostname]' command.(Error 401: Unauthorized)
2023-10-19 11:21:24,518 ERROR   MainThread:16838 [wandb_init.py:init():1183] The API key you provided is either invalid or missing.  If the `WANDB_API_KEY` environment variable is set, make sure it is correct. Otherwise, to resolve this issue, you may try running the 'wandb login --relogin' command. If you are using a local server, make sure that you're using the correct hostname. If you're not sure, you can try logging in again using the 'wandb login --relogin --host [hostname]' command.(Error 401: Unauthorized)
Traceback (most recent call last):
  File "/home/yasin/anaconda3/lib/python3.9/site-packages/wandb/sdk/wandb_init.py", line 1165, in init
    run = wi.init()
  File "/home/yasin/anaconda3/lib/python3.9/site-packages/wandb/sdk/wandb_init.py", line 780, in init
    raise error
wandb.errors.AuthenticationError: The API key you provided is either invalid or missing.  If the `WANDB_API_KEY` environment variable is set, make sure it is correct. Otherwise, to resolve this issue, you may try running the 'wandb login --relogin' command. If you are using a local server, make sure that you're using the correct hostname. If you're not sure, you can try logging in again using the 'wandb login --relogin --host [hostname]' command.(Error 401: Unauthorized)
2023-10-19 11:21:25,520 WARNING MsgRouterThr:16838 [router.py:message_loop():77] message_loop has been closed
